<?xml version="1.0" ?>

<robot name="soccerbot" xmlns:xacro="http://www.ros.org/wiki/xacro">

    <xacro:property name="PI" value="3.1415926535897931"/>

    <xacro:include filename="$(find soccer_description)/models/soccerbot/model.gazebo" />
    <!-- Import Rviz colors -->
    <xacro:include filename="$(find soccer_description)/models/soccerbot/materials.xacro" />

    <!-- Links -->
    <link name="base_link" />
    <link name="torso">
        <inertial>
            <mass value="1529.201"/>
            <origin rpy="0 0 0" xyz="0.0082498 -0.0017440 -0.0522479"/>
            <inertia ixx="4.323" ixy="0.006" ixz="0.040" iyy="5.198" iyz="-0.015" izz="3.567"/>
        </inertial>
        <collision name="collision">
            <origin rpy="0 0 0" xyz="0 0 -0.052"/>
            <geometry>
                <box size="0.130 0.145 0.152"/>
            </geometry>
        </collision>
        <visual name="visual">
            <origin rpy="0 0 0" xyz="0 0 0"/>
            <geometry>
                <mesh filename="package://soccer_description/meshes/soccerbot v4/Torso.dae" scale="1 1 1"/>
            </geometry>
        </visual>
    </link>
    <link name="camera" />
    <link name="imu_link" />
    <link name="neck">
        <inertial>
            <mass value="11.294"/>
            <origin rpy="0  0  0" xyz="0 -0.0006476 0.0092453"/>
            <inertia ixx="0.005" ixy="0" ixz="0" iyy="0.001" iyz="0" izz="0.005"/>
        </inertial>
        <collision name="collision">
            <origin rpy="0  0  0" xyz="0 0 0.0165"/>
            <geometry>
                <box size="0.022 0.0523 0.033"/>
            </geometry>
        </collision>
        <visual name="visual">
            <origin rpy="0  0  0" xyz="0  0  0"/>
            <geometry>
                <mesh filename="package://soccer_description/meshes/soccerbot v4/Neck.dae" scale="1 1 1"/>
            </geometry>
            <material name="black" />
        </visual>
    </link>
    <link name="head">
        <inertial>
            <mass value="282.919"/>
            <origin rpy="0  0  0" xyz="0.0237166 0.0018096 0.0255966"/>
            <inertia ixx="0.206" ixy="0.001" ixz="-0.057" iyy="0.206" iyz="0.003" izz="0.160"/>
        </inertial>
        <collision name="collision">
            <origin rpy="0  0  0" xyz="0.01735 0 0.01995"/>
            <geometry>
                <box size="0.0712 0.094 0.0839"/>
            </geometry>
        </collision>
        <visual name="visual">
            <origin rpy="0  0  0" xyz="0  0  0"/>
            <geometry>
                <mesh filename="package://soccer_description/meshes/soccerbot v4/Head.dae" scale="1 1 1"/>
            </geometry>
            <material name="black" />
        </visual>
    </link>

    <link name="right_hip_side">
        <inertial>
            <mass value="9.364"/>
            <origin rpy="0  0  0" xyz="0.0003695 0.0000 0.01689"/>
            <inertia ixx="0.002" ixy="0.000" ixz="0.000" iyy="0.005" iyz="0.000" izz="0.004"/>
        </inertial>
        <collision name="collision">
            <origin rpy="0  0  0" xyz="0 0 0.00899"/>
            <geometry>
                <box size="0.0475 0.022 0.039"/>
            </geometry>
        </collision>
        <visual name="visual">
            <origin rpy="0  0  0" xyz="0  0  0"/>
            <geometry>
                <mesh filename="package://soccer_description/meshes/soccerbot v4/Right Hip Side.dae" scale="1 1 1"/>
            </geometry>
            <material name="black" />
        </visual>
    </link>
    <link name="right_hip_front">
        <inertial>
            <mass value="153.186"/>
            <origin rpy="0 0 0" xyz="-0.02093 0 -0.011313"/>
            <inertia ixx="0.041" ixy="0.000" ixz="-0.002" iyy="0.118" iyz="0.000" izz="0.106"/>
        </inertial>
        <collision name="collision">
            <origin rpy="0 0 0" xyz="-0.02187 0 -0.01332"/>
            <geometry>
                <box size="0.083747 0.04885 0.0506"/>
            </geometry>
        </collision>
        <visual name="visual">
            <origin rpy="0  0  0" xyz="0  0  0"/>
            <geometry>
                <mesh filename="package://soccer_description/meshes/soccerbot v4/Right Hip Front.dae" scale="1 1 1"/>
            </geometry>
            <material name="black" />
        </visual>
    </link>
    <link name="right_thigh">
        <inertial>
            <mass value="21.438"/>
            <origin rpy="0 0 0" xyz="0.0019422 0.0001419 -0.0469409"/>
            <inertia ixx="0.025" ixy="0.002" ixz="0.000" iyy="0.016" iyz="0.000" izz="0.010"/>
        </inertial>
        <collision name="collision">
            <origin rpy="0 0 0" xyz="0 0 -0.0445"/>
            <geometry>
                <box size="0.022 0.048 0.111"/>
            </geometry>
        </collision>
        <visual name="visual">
            <origin rpy="0  0  0" xyz="0  0  0"/>
            <geometry>
                <mesh filename="package://soccer_description/meshes/soccerbot v4/Right Thigh.dae" scale="1 1 1"/>
            </geometry>
            <material name="black" />
        </visual>
    </link>
    <link name="right_calve">
        <inertial>
            <mass value="86.547"/>
            <origin rpy="0  0  0" xyz="0 -0.0003259 -0.0150123"/>
            <inertia ixx="0.054" ixy="0.000" ixz="0.000" iyy="0.046" iyz="0.001" izz="0.019"/>
        </inertial>
        <collision name="collision">
            <origin rpy="0 0 0" xyz="0 0 -0.03385"/>
            <geometry>
                <box size="0.031883 0.048 0.105683"/>
            </geometry>
        </collision>
        <visual name="visual">
            <origin rpy="0 0 0" xyz="0 0 -0.0827"/>
            <geometry>
                <mesh filename="package://soccer_description/meshes/soccerbot v4/Right Calve.dae" scale="1 1 1"/>
            </geometry>
            <material name="black" />
        </visual>
    </link>
    <link name="right_ankle">
        <inertial>
            <mass value="153.186"/>
            <origin rpy="0 0 0" xyz="-0.020939 0.000 0.011313"/>
            <inertia ixx="0.041" ixy="0.000" ixz="0.002" iyy="0.118" iyz="0.000" izz="0.106"/>
        </inertial>
        <collision name="collision">
            <origin rpy="0 0 0" xyz="-0.02014 0 0.01031"/>
            <geometry>
                <box size="0.090769 0.042 0.0506"/>
            </geometry>
        </collision>
        <visual name="visual">
            <origin rpy="0  0  0" xyz="0  0  0"/>
            <geometry>
                <mesh filename="package://soccer_description/meshes/soccerbot v4/Right Ankle.dae" scale="1 1 1"/>
            </geometry>
            <material name="black" />
        </visual>
    </link>
    <link name="right_foot">
        <inertial>
            <mass value="23.216"/>
            <origin rpy="0 0 0" xyz="-0.020939 0.0 0.011313"/>
            <inertia ixx="0.006" ixy="0.000" ixz="0.000" iyy="0.018" iyz="0.000" izz="0.022"/>
        </inertial>
        <collision name="collision">
            <origin rpy="0 0 0" xyz="0.00385 -0.00401 -0.00737"/>
            <geometry>
                <box size="0.09 0.07 0.03674"/>
            </geometry>
            <contact_coefficients mu ="100.0" />
        </collision>
        <visual name="visual">
            <origin rpy="0  0  0" xyz="0  0  0"/>
            <geometry>
                <mesh filename="package://soccer_description/meshes/soccerbot v4/Right Foot.dae" scale="1 1 1"/>
            </geometry>
            <material name="black" />
        </visual>
    </link>

    <link name="left_hip_side">
        <inertial>
            <mass value="9.364"/>
            <origin rpy="0  0  0" xyz="0.0003695 0.0000 0.01689"/>
            <inertia ixx="0.002" ixy="0.000" ixz="0.000" iyy="0.005" iyz="0.000" izz="0.004"/>
        </inertial>
        <collision name="collision">
            <origin rpy="0  0  0" xyz="0 0 0.00899"/>
            <geometry>
                <box size="0.0485 0.022 0.0039"/>
            </geometry>
        </collision>
        <visual name="visual">
            <origin rpy="0  0  0" xyz="0  0  0"/>
            <geometry>
                <mesh filename="package://soccer_description/meshes/soccerbot v4/Left Hip Side.dae" scale="1 1 1"/>
            </geometry>
            <material name="black" />
        </visual>
    </link>
    <link name="left_hip_front">
        <inertial>
            <mass value="153.186"/>
            <origin rpy="0 0 0" xyz="-0.02093 0 -0.011313"/>
            <inertia ixx="0.041" ixy="0.000" ixz="-0.002" iyy="0.118" iyz="0.000" izz="0.106"/>
        </inertial>
        <collision name="collision">
            <origin rpy="0 0 0" xyz="-0.02187 0 -0.01332"/>
            <geometry>
                <box size="0.083747 0.04885 0.0506"/>
            </geometry>
        </collision>
        <visual name="visual">
            <origin rpy="0  0  0" xyz="0  0  0"/>
            <geometry>
                <mesh filename="package://soccer_description/meshes/soccerbot v4/Left Hip Front.dae" scale="1 1 1"/>
            </geometry>
            <material name="black" />
        </visual>
    </link>
    <link name="left_thigh">
        <inertial>
            <mass value="21.438"/>
            <origin rpy="0 0 0" xyz="0.0019422 -0.0001419 -0.0469409"/>
            <inertia ixx="0.025" ixy="-0.002" ixz="0.000" iyy="0.016" iyz="0.000" izz="0.010"/>
        </inertial>
        <collision name="collision">
            <origin rpy="0 0 0" xyz="0 0 -0.0445"/>
            <geometry>
                <box size="0.022 0.048 0.111"/>
            </geometry>
        </collision>
        <visual name="visual">
            <origin rpy="0  0  0" xyz="0  0  0"/>
            <geometry>
                <mesh filename="package://soccer_description/meshes/soccerbot v4/Left Thigh.dae" scale="1 1 1"/>
            </geometry>
            <material name="black" />
        </visual>
    </link>
    <link name="left_calve">
        <inertial>
            <mass value="86.547"/>
            <origin rpy="0  0  0" xyz="0 0.0003259 -0.0150123"/>
            <inertia ixx="0.054" ixy="0.000" ixz="0.000" iyy="0.046" iyz="-0.001" izz="0.019"/>
        </inertial>
        <collision name="collision">
            <origin rpy="0 0 0" xyz="0 0 -0.03385"/>
            <geometry>
                <box size="0.031883 0.048 0.105683"/>
            </geometry>
        </collision>
        <visual name="visual">
            <origin rpy="0 0 0" xyz="0 0 -0.0827"/>
            <geometry>
                <mesh filename="package://soccer_description/meshes/soccerbot v4/Left Calve.dae" scale="1 1 1"/>
            </geometry>
            <material name="black" />
        </visual>
    </link>
    <link name="left_ankle">
        <inertial>
            <mass value="153.186"/>
            <origin rpy="0 0 0" xyz="-0.020939 0.000 0.011313"/>
            <inertia ixx="0.041" ixy="0.000" ixz="0.002" iyy="0.118" iyz="0.000" izz="0.106"/>
        </inertial>
        <collision name="collision">
            <origin rpy="0 0 0" xyz="-0.02014 0 0.01031"/>
            <geometry>
                <box size="0.090769 0.042 0.0506"/>
            </geometry>
        </collision>
        <visual name="visual">
            <origin rpy="0 0 0" xyz="0  0  0"/>
            <geometry>
                <mesh filename="package://soccer_description/meshes/soccerbot v4/Left Ankle.dae" scale="1 1 1"/>
            </geometry>
            <material name="black" />
        </visual>
    </link>
    <link name="left_foot">
        <inertial>
            <mass value="23.216"/>
            <origin rpy="0 0 0" xyz="-0.020939 0.0 0.011313"/>
            <inertia ixx="0.006" ixy="0.000" ixz="0.000" iyy="0.018" iyz="0.000" izz="0.022"/>
        </inertial>
        <collision name="collision">
            <origin rpy="0 0 0" xyz="0.00385 0.00401 -0.00737 "/>
            <geometry>
                <box size="0.09 0.07 0.03674"/>
            </geometry>
            <contact_coefficients mu ="100.0" />

        </collision>
        <visual name="visual">
            <origin rpy="0  0  0" xyz="0  0  0"/>
            <geometry>
                <mesh filename="package://soccer_description/meshes/soccerbot v4/Left Foot.dae" scale="1 1 1"/>
            </geometry>
            <material name="black" />
        </visual>
    </link>

    <link name="right_bicep">
        <inertial>
            <mass value="213.5130"/>
            <origin rpy="0  0  0" xyz="0.000 0.02579 -0.04955"/>
            <inertia ixx="0.282" ixy="0.000" ixz="0.000" iyy="0.274" iyz="0.012" izz="0.024" />
        </inertial>
        <collision name="collision">
            <origin rpy="0  0  0" xyz="0 0.0225 -0.05001"/>
            <geometry>
                <box size="0.04 0.04776 0.123"/>
            </geometry>
        </collision>
        <visual name="visual">
            <origin rpy="0  0  0" xyz="0  0  0"/>
            <geometry>
                <mesh filename="package://soccer_description/meshes/soccerbot v4/Right Bicep.dae" scale="1 1 1"/>
            </geometry>
            <material name="black" />
        </visual>
    </link>
    <link name="right_forearm">
        <inertial>
            <mass value="45.7"/>
            <origin rpy="0  0  0" xyz="0 0.0245 -0.0546097" />
            <inertia ixx="0.113" ixy="0.000" ixz="0.001" iyy="0.107" iyz="0.000" izz="0.012" />
        </inertial>
        <collision name="collision">
            <origin rpy="0  0  0" xyz="-0.0055 0.01750 -0.0600"/>
            <geometry>
                <box size="0.035 0.049 0.144"/>
            </geometry>
        </collision>
        <visual name="visual">
            <origin rpy="0  0  0" xyz="0  0  0"/>
            <geometry>
                <mesh filename="package://soccer_description/meshes/soccerbot v4/Right Forearm.dae" scale="1 1 1"/>
            </geometry>
            <material name="black" />
        </visual>
    </link>

    <link name="left_bicep">
        <inertial>
            <mass value="213.5130"/>
            <origin rpy="0  0  0" xyz="0.000 -0.02579 -0.04955"/>
            <inertia ixx="0.282" ixy="0.000" ixz="0.000" iyy="0.274" iyz="-0.012" izz="0.024" />
        </inertial>
        <collision name="collision">
            <origin rpy="0  0  0" xyz="0 -0.0225 -0.05001"/>
            <geometry>
                <box size="0.04 0.047 0.123"/>
            </geometry>
        </collision>
        <visual name="visual">
            <origin rpy="0  0  0" xyz="0  0  0"/>
            <geometry>
                <mesh filename="package://soccer_description/meshes/soccerbot v4/Left Bicep.dae" scale="1 1 1"/>
            </geometry>
            <material name="black" />
        </visual>
    </link>
    <link name="left_forearm">
        <inertial>
            <mass value="45.7"/>
            <origin rpy="0  0  0" xyz="0 -0.0245 -0.0546097" />
            <inertia ixx="0.113" ixy="0.000" ixz="-0.001" iyy="0.107" iyz="0.000" izz="0.012" />
        </inertial>
        <collision name="collision">
            <origin rpy="0  0  0" xyz="-0.0055 -0.01750 -0.06001"/>
            <geometry>
                <box size="0.035 0.049 0.144"/>
            </geometry>
        </collision>
        <visual name="visual">
            <origin rpy="0  0  0" xyz="0  0  0"/>
            <geometry>
                <mesh filename="package://soccer_description/meshes/soccerbot v4/Left Forearm.dae" scale="1 1 1"/>
            </geometry>
            <material name="black" />
        </visual>
    </link>

    <!-- Joints -->
    <joint name="base_link_torso" type="fixed">
        <parent link="base_link"/>
        <child link="torso"/>
        <origin rpy="0 0 0" xyz="0 0 0.3536"/>
        <axis xyz="1 0 0"/>
    </joint>

    <joint name="torso_imu" type="fixed">
        <parent link="torso"/>
        <child link="imu_link"/>
        <origin rpy="0 0 0" xyz="0.1 0 0.0075"/>
        <axis xyz="0 0 0"/>
    </joint>

    <joint name="torso_right_hip_side" type="revolute">
        <parent link="torso"/>
        <child link="right_hip_side"/>
        <origin rpy="0 0 0" xyz="0.0135 0.035 -0.156"/>
        <axis xyz="0 0 -1"/>
        <dynamics damping="0.0" friction="2000.0" />
        <limit effort="31000.0" lower="-1.309" upper="0.524" velocity="1.0"/>
    </joint>
    <joint name="right_hip_side_hip_front" type="revolute">
        <parent link="right_hip_side"/>
        <child link="right_hip_front"/>
        <origin rpy="0 0 0" xyz="0 0 0"/>
        <axis xyz="-1 0 0"/>
        <dynamics damping="0.0" friction="2000.0" />
        <limit effort="31000.0" lower="-0.785" upper="1.571" velocity="1.0"/>
    </joint>
    <joint name="right_hip_front_thigh" type="revolute">
        <parent link="right_hip_front"/>
        <child link="right_thigh"/>
        <origin rpy="0 0 0" xyz="0 0 0"/>
        <axis xyz="0 -1 0"/>
        <dynamics damping="0.0" friction="2000.0" />
        <limit effort="31000.0" lower="-0.785" upper="2.356" velocity="1.0"/>
    </joint>
    <joint name="right_thigh_calve" type="revolute">
        <parent link="right_thigh"/>
        <child link="right_calve"/>
        <origin rpy="0 0 0" xyz="0 0 -0.0929"/>
        <axis xyz="0 -1 0"/>
        <dynamics damping="0.0" friction="2000.0" />
        <limit effort="31000.0" lower="-2.793" upper="0" velocity="1.0"/>
    </joint>
    <joint name="right_calve_ankle" type="revolute">
        <parent link="right_calve"/>
        <child link="right_ankle"/>
        <origin rpy="0 0 0" xyz="0 0 -0.0827"/>
        <axis xyz="0 -1 0"/>
        <dynamics damping="0.0" friction="2000.0" />
        <limit effort="31000.0" lower="-0.785" upper="1.571" velocity="1.0"/>
    </joint>
    <joint name="right_ankle_foot" type="revolute">
        <parent link="right_ankle"/>
        <child link="right_foot"/>
        <origin rpy="0 0 0" xyz="0 0 0"/>
        <axis xyz="-1 0 0"/>
        <dynamics damping="0.0" friction="2000.0" />
        <limit effort="31000.0" lower="-0.785" upper="0.785" velocity="1.0"/>
    </joint>

    <joint name="torso_left_hip_side" type="revolute">
        <parent link="torso"/>
        <child link="left_hip_side"/>
        <origin rpy="0 0 0" xyz="0.0135 -0.035 -0.156"/>
        <axis xyz="0 0 1"/>
        <dynamics damping="0.0" friction="2000.0" />
        <limit effort="31000.0" lower="-1.309" upper="0.524" velocity="1.0"/>
    </joint>
    <joint name="left_hip_side_hip_front" type="revolute">
        <parent link="left_hip_side"/>
        <child link="left_hip_front"/>
        <origin rpy="0 0 0" xyz="0 0 0"/>
        <axis xyz="-1 0 0"/>
        <dynamics damping="0.0" friction="2000.0" />
        <limit effort="31000.0" lower="-1.571" upper="0.785" velocity="1.0"/>
    </joint>
    <joint name="left_hip_front_thigh" type="revolute">
        <parent link="left_hip_front"/>
        <child link="left_thigh"/>
        <origin rpy="0 0 0" xyz="0 0 0"/>
        <axis xyz="0 -1 0"/>
        <dynamics damping="0.0" friction="2000.0" />
        <limit effort="31000.0" lower="-0.785" upper="2.356" velocity="1.0"/>
    </joint>
    <joint name="left_thigh_calve" type="revolute">
        <parent link="left_thigh"/>
        <child link="left_calve"/>
        <origin rpy="0 0 0" xyz="0 0 -0.09290"/>
        <axis xyz="0 -1 0"/>
        <dynamics damping="0.0" friction="2000.0" />
        <limit effort="31000.0" lower="-2.793" upper="0" velocity="1.0"/>
    </joint>
    <joint name="left_calve_ankle" type="revolute">
        <parent link="left_calve"/>
        <child link="left_ankle"/>
        <origin rpy="0 0 0" xyz="0 0 -0.0827"/>
        <axis xyz="0 -1 0"/>
        <dynamics damping="0.0" friction="2000.0" />
        <limit effort="31000.0" lower="-0.785" upper="1.571" velocity="1.0"/>
    </joint>
    <joint name="left_ankle_foot" type="revolute">
        <parent link="left_ankle"/>
        <child link="left_foot"/>
        <origin rpy="0 0 0" xyz="0 0 0"/>
        <axis xyz="-1 0 0"/>
        <dynamics damping="0.0" friction="2000.0" />
        <limit effort="31000.0" lower="-0.785" upper="0.785" velocity="1.0"/>
    </joint>

    <joint name="torso_neck" type="revolute">
        <parent link="torso"/>
        <child link="neck"/>
        <origin rpy="0 0 0" xyz="0.024 0 0.05875"/>
        <axis xyz="0 0 1"/>
        <dynamics damping="0.0" friction="2000.0" />
        <limit effort="15000.0" lower="-1.571" upper="1.571" velocity="1.0"/>
    </joint>
    <joint name="neck_head" type="revolute">
        <parent link="neck"/>
        <child link="head"/>
        <origin rpy="0 0 0" xyz="0 0 0.024"/>
        <axis xyz="0 1 0"/>
        <dynamics damping="0.0" friction="2000.0" />
        <limit effort="15000.0" lower="-2.356" upper="2.356" velocity="1.0"/>
    </joint>
    <joint name="head_camera" type="fixed">
        <parent link="head"/>
        <child link="camera"/>
        <origin rpy="0 0 0" xyz="0.05295 0.00145 0.04740"/>
        <axis xyz="0  0  0"/>
        <dynamics damping="0.0" friction="2000.0" />
        <limit effort="0" lower="0" upper="0" velocity="0"/>
    </joint>

    <joint name="torso_right_bicep" type="revolute">
        <parent link="torso"/>
        <child link="right_bicep"/>
        <origin rpy="0 0 0" xyz="-0.0157 0.0725 0"/>
        <axis xyz="0 -1 0"/>
        <dynamics damping="0.0" friction="2000.0" />
        <limit effort="15000.0" lower="-1.571" upper="3.927" velocity="1.0"/>
    </joint>
    <joint name="right_bicep_forearm" type="revolute">
        <parent link="right_bicep"/>
        <child link="right_forearm"/>
        <origin rpy="0 0 0" xyz="0 0 -0.10"/>
        <axis xyz="0 -1 0"/>
        <dynamics damping="0.0" friction="2000.0" />
        <limit effort="15000.0" lower="0" upper="3.14159" velocity="1.0"/>
    </joint>

    <joint name="torso_left_bicep" type="revolute">
        <parent link="torso"/>
        <child link="left_bicep"/>
        <origin rpy="0 0 0" xyz="-0.0157 -0.0725 0"/>
        <axis xyz="0 -1 0"/>
        <dynamics damping="0.0" friction="2000.0" />
        <limit effort="15000.0" lower="-1.571" upper="3.927" velocity="1.0"/>
    </joint>
    <joint name="left_bicep_forearm" type="revolute">
        <parent link="left_bicep"/>
        <child link="left_forearm"/>
        <origin rpy="0 0 0" xyz="0 0 -0.10"/>
        <axis xyz="0 -1 0"/>
        <dynamics damping="0.0" friction="2000.0" />
        <limit effort="15000.0" lower="0" upper="3.14159" velocity="1.0"/>
    </joint>

    <!-- Transmission -->
    <transmission name="torso_right_hip_side">
        <type>transmission_interface/SimpleTransmission</type>
        <joint name="torso_right_hip_side">
            <hardwareInterface>hardware_interface/EffortJointInterface</hardwareInterface>
        </joint>
        <actuator name="motor7">
            <hardwareInterface>hardware_interface/EffortJointInterface</hardwareInterface>
            <mechanicalReduction>1</mechanicalReduction>
        </actuator>
    </transmission>
    <transmission name="right_hip_side_hip_front">
        <type>transmission_interface/SimpleTransmission</type>
        <joint name="right_hip_side_hip_front">
            <hardwareInterface>hardware_interface/EffortJointInterface</hardwareInterface>
        </joint>
        <actuator name="motor8">
            <hardwareInterface>hardware_interface/EffortJointInterface</hardwareInterface>
            <mechanicalReduction>1</mechanicalReduction>
        </actuator>
    </transmission>
    <transmission name="right_hip_front_thigh">
        <type>transmission_interface/SimpleTransmission</type>
        <joint name="right_hip_front_thigh">
            <hardwareInterface>hardware_interface/EffortJointInterface</hardwareInterface>
        </joint>
        <actuator name="motor9">
            <hardwareInterface>hardware_interface/EffortJointInterface</hardwareInterface>
            <mechanicalReduction>1</mechanicalReduction>
        </actuator>
    </transmission>
    <transmission name="right_thigh_calve">
        <type>transmission_interface/SimpleTransmission</type>
        <joint name="right_thigh_calve">
            <hardwareInterface>hardware_interface/EffortJointInterface</hardwareInterface>
        </joint>
        <actuator name="motor10">
            <hardwareInterface>hardware_interface/EffortJointInterface</hardwareInterface>
            <mechanicalReduction>1</mechanicalReduction>
        </actuator>
    </transmission>
    <transmission name="right_calve_ankle">
        <type>transmission_interface/SimpleTransmission</type>
        <joint name="right_calve_ankle">
            <hardwareInterface>hardware_interface/EffortJointInterface</hardwareInterface>
        </joint>
        <actuator name="motor11">
            <hardwareInterface>hardware_interface/EffortJointInterface</hardwareInterface>
            <mechanicalReduction>1</mechanicalReduction>
        </actuator>
    </transmission>
    <transmission name="right_ankle_foot">
        <type>transmission_interface/SimpleTransmission</type>
        <joint name="right_ankle_foot">
            <hardwareInterface>hardware_interface/EffortJointInterface</hardwareInterface>
        </joint>
        <actuator name="motor12">
            <hardwareInterface>hardware_interface/EffortJointInterface</hardwareInterface>
            <mechanicalReduction>1</mechanicalReduction>
        </actuator>
    </transmission>

    <transmission name="torso_left_hip_side">
        <type>transmission_interface/SimpleTransmission</type>
        <joint name="torso_left_hip_side">
            <hardwareInterface>hardware_interface/EffortJointInterface</hardwareInterface>
        </joint>
        <actuator name="motor6">
            <hardwareInterface>hardware_interface/EffortJointInterface</hardwareInterface>
            <mechanicalReduction>1</mechanicalReduction>
        </actuator>
    </transmission>
    <transmission name="left_hip_side_hip_front">
        <type>transmission_interface/SimpleTransmission</type>
        <joint name="left_hip_side_hip_front">
            <hardwareInterface>hardware_interface/EffortJointInterface</hardwareInterface>
        </joint>
        <actuator name="motor5">
            <hardwareInterface>hardware_interface/EffortJointInterface</hardwareInterface>
            <mechanicalReduction>1</mechanicalReduction>
        </actuator>
    </transmission>
    <transmission name="left_hip_front_thigh">
        <type>transmission_interface/SimpleTransmission</type>
        <joint name="left_hip_front_thigh">
            <hardwareInterface>hardware_interface/EffortJointInterface</hardwareInterface>
        </joint>
        <actuator name="motor4">
            <hardwareInterface>hardware_interface/EffortJointInterface</hardwareInterface>
            <mechanicalReduction>1</mechanicalReduction>
        </actuator>
    </transmission>
    <transmission name="left_thigh_calve">
        <type>transmission_interface/SimpleTransmission</type>
        <joint name="left_thigh_calve">
            <hardwareInterface>hardware_interface/EffortJointInterface</hardwareInterface>
        </joint>
        <actuator name="motor3">
            <hardwareInterface>hardware_interface/EffortJointInterface</hardwareInterface>
            <mechanicalReduction>1</mechanicalReduction>
        </actuator>
    </transmission>
    <transmission name="left_calve_ankle">
        <type>transmission_interface/SimpleTransmission</type>
        <joint name="left_calve_ankle">
            <hardwareInterface>hardware_interface/EffortJointInterface</hardwareInterface>
        </joint>
        <actuator name="motor2">
            <hardwareInterface>hardware_interface/EffortJointInterface</hardwareInterface>
            <mechanicalReduction>1</mechanicalReduction>
        </actuator>
    </transmission>
    <transmission name="left_ankle_foot">
        <type>transmission_interface/SimpleTransmission</type>
        <joint name="left_ankle_foot">
            <hardwareInterface>hardware_interface/EffortJointInterface</hardwareInterface>
        </joint>
        <actuator name="motor1">
            <hardwareInterface>hardware_interface/EffortJointInterface</hardwareInterface>
            <mechanicalReduction>1</mechanicalReduction>
        </actuator>
    </transmission>

    <transmission name="torso_neck">
        <type>transmission_interface/SimpleTransmission</type>
        <joint name="torso_neck">
            <hardwareInterface>hardware_interface/EffortJointInterface</hardwareInterface>
        </joint>
        <actuator name="motor13">
            <hardwareInterface>hardware_interface/EffortJointInterface</hardwareInterface>
            <mechanicalReduction>1</mechanicalReduction>
        </actuator>
    </transmission>
    <transmission name="neck_head">
        <type>transmission_interface/SimpleTransmission</type>
        <joint name="neck_head">
            <hardwareInterface>hardware_interface/EffortJointInterface</hardwareInterface>
        </joint>
        <actuator name="motor14">
            <hardwareInterface>hardware_interface/EffortJointInterface</hardwareInterface>
            <mechanicalReduction>1</mechanicalReduction>
        </actuator>
    </transmission>

    <transmission name="torso_right_bicep">
        <type>transmission_interface/SimpleTransmission</type>
        <joint name="torso_right_bicep">
            <hardwareInterface>hardware_interface/EffortJointInterface</hardwareInterface>
        </joint>
        <actuator name="motor15">
            <hardwareInterface>hardware_interface/EffortJointInterface</hardwareInterface>
            <mechanicalReduction>1</mechanicalReduction>
        </actuator>
    </transmission>
    <transmission name="right_bicep_forearm">
        <type>transmission_interface/SimpleTransmission</type>
        <joint name="right_bicep_forearm">
            <hardwareInterface>hardware_interface/EffortJointInterface</hardwareInterface>
        </joint>
        <actuator name="motor16">
            <hardwareInterface>hardware_interface/EffortJointInterface</hardwareInterface>
            <mechanicalReduction>1</mechanicalReduction>
        </actuator>
    </transmission>

    <transmission name="torso_left_bicep">
        <type>transmission_interface/SimpleTransmission</type>
        <joint name="torso_left_bicep">
            <hardwareInterface>hardware_interface/EffortJointInterface</hardwareInterface>
        </joint>
        <actuator name="motor17">
            <hardwareInterface>hardware_interface/EffortJointInterface</hardwareInterface>
            <mechanicalReduction>1</mechanicalReduction>
        </actuator>
    </transmission>
    <transmission name="left_bicep_forearm">
        <type>transmission_interface/SimpleTransmission</type>
        <joint name="left_bicep_forearm">
            <hardwareInterface>hardware_interface/EffortJointInterface</hardwareInterface>
        </joint>
        <actuator name="motor18">
            <hardwareInterface>hardware_interface/EffortJointInterface</hardwareInterface>
            <mechanicalReduction>1</mechanicalReduction>
        </actuator>
    </transmission>/

</robot>
